Status: Failed
Test Event Name: test

Response:
{
  "errorMessage": "Invalid event, no requestContext provided",
  "errorType": "RuntimeError",
  "requestId": "52faebfb-7bfa-4e34-ad05-f6d005e80af4",
  "stackTrace": [
    "  File \"/var/task/model_function.py\", line 143, in lambda_handler\n    result = dispatcher_helper.dispatch_method(dispatch_table, event)\n",
    "  File \"/var/task/utils/dispatcher_helper.py\", line 119, in dispatch_method\n    authorizer = _get_request_context_authorizer(event)\n",
    "  File \"/var/task/utils/dispatcher_helper.py\", line 47, in _get_request_context_authorizer\n    raise RuntimeError(\"Invalid event, no requestContext provided\")\n"
  ]
}

Function Logs:
06-Jun-25 07:09:16 - INFO - Using default logging config without output log file
START RequestId: 52faebfb-7bfa-4e34-ad05-f6d005e80af4 Version: $LATEST
06-Jun-25 07:09:16 - INFO - Invokation params: {'key1': 'value1', 'key2': 'value2', 'key3': 'value3'}
06-Jun-25 07:09:16 - WARNING - LAMBDA_WARNING: Unhandled exception. The most likely cause is an issue in the function code. However, in rare cases, a Lambda runtime update can cause unexpected function behavior. For functions using managed runtimes, runtime updates can be triggered by a function change, or can be applied automatically. To determine if the runtime has been updated, check the runtime version in the INIT_START log entry. If this error correlates with a change in the runtime version, you may be able to mitigate this error by temporarily rolling back to the previous runtime version. For more information, see https://docs.aws.amazon.com/lambda/latest/dg/runtimes-update.html
[ERROR] RuntimeError: Invalid event, no requestContext provided
Traceback (most recent call last):
  File "/var/task/model_function.py", line 143, in lambda_handler
    result = dispatcher_helper.dispatch_method(dispatch_table, event)
  File "/var/task/utils/dispatcher_helper.py", line 119, in dispatch_method
    authorizer = _get_request_context_authorizer(event)
  File "/var/task/utils/dispatcher_helper.py", line 47, in _get_request_context_authorizer
    raise RuntimeError("Invalid event, no requestContext provided")
END RequestId: 52faebfb-7bfa-4e34-ad05-f6d005e80af4
REPORT RequestId: 52faebfb-7bfa-4e34-ad05-f6d005e80af4	Duration: 53.22 ms	Billed Duration: 54 ms	Memory Size: 128 MB	Max Memory Used: 128 MB	Init Duration: 5608.16 ms

Request ID: 52faebfb-7bfa-4e34-ad05-f6d005e80af4
