venv) sagemaker-user@default:~/f1_ai_mlops_baseline$ python python_scripts/utils/f1ai_model_promoter.py 
Warning: Could not generate AWS temporary credentials. Please make sure you have the necessary permissions.
Traceback (most recent call last):
  File "/home/sagemaker-user/f1_ai_mlops_baseline/python_scripts/utils/f1ai_model_promoter.py", line 22, in <module>
    process() 
    ^^^^^^^^^
  File "/home/sagemaker-user/f1_ai_mlops_baseline/python_scripts/utils/f1ai_model_promoter.py", line 13, in process
    response_json = client.promote_model_registration(
                    ^^^^^^^^^^^^^^^^^^^^^^^^^^^^^^^^^^
  File "/home/sagemaker-user/f1_ai_mlops_baseline/venv/lib/python3.12/site-packages/f1ai_client/f1ai_client.py", line 1405, in promote_model_registration
    return _transform_response(response)
           ^^^^^^^^^^^^^^^^^^^^^^^^^^^^^
  File "/home/sagemaker-user/f1_ai_mlops_baseline/venv/lib/python3.12/site-packages/f1ai_client/f1ai_client.py", line 26, in _transform_response
    raise RuntimeError(f"{response.reason=}, {response.content=}")
RuntimeError: response.reason='Bad Gateway', response.content=b'{"message": "Internal server error"}'
(venv) sagemaker-use
